/var/www/agentarbitrage/venv/lib/python3.10/site-packages/celery/platforms.py:829: SecurityWarning: You're running the worker with superuser privileges: this is
absolutely not recommended!

Please specify a different user using the --uid option.

User information: uid=0 euid=0 gid=0 egid=0

  warnings.warn(SecurityWarning(ROOT_DISCOURAGED.format(
Loading celery_config.py
celery_config.py loaded successfully
 
 -------------- celery@srv934846 v5.3.6 (emerald-rush)
--- ***** ----- 
-- ******* ---- Linux-5.15.0-151-generic-x86_64-with-glibc2.35 2025-10-12 02:15:05
- *** --- * --- 
- ** ---------- [config]
- ** ---------- .> app:         agentarbitrage:0x7f2b1e825600
- ** ---------- .> transport:   redis://127.0.0.1:6379/0
- ** ---------- .> results:     redis://127.0.0.1:6379/0
- *** --- * --- .> concurrency: 1 (prefork)
-- ******* ---- .> task events: OFF (enable -E to monitor tasks in this worker)
--- ***** ----- 
 -------------- [queues]
                .> celery           exchange=celery(direct) key=celery
                

[tasks]
  . keepa_deals.Keepa_Deals.recalculate_deals
  . keepa_deals.Keepa_Deals.run_keepa_script

[2025-10-12 02:15:05,570: WARNING/MainProcess] /var/www/agentarbitrage/venv/lib/python3.10/site-packages/celery/worker/consumer/consumer.py:507: CPendingDeprecationWarning: The broker_connection_retry configuration setting will no longer determine
whether broker connection retries are made during startup in Celery 6.0 and above.
If you wish to retain the existing behavior for retrying connections on startup,
you should set broker_connection_retry_on_startup to True.
  warnings.warn(

[2025-10-12 02:15:05,582: INFO/MainProcess] Connected to redis://127.0.0.1:6379/0
[2025-10-12 02:15:05,582: WARNING/MainProcess] /var/www/agentarbitrage/venv/lib/python3.10/site-packages/celery/worker/consumer/consumer.py:507: CPendingDeprecationWarning: The broker_connection_retry configuration setting will no longer determine
whether broker connection retries are made during startup in Celery 6.0 and above.
If you wish to retain the existing behavior for retrying connections on startup,
you should set broker_connection_retry_on_startup to True.
  warnings.warn(

[2025-10-12 02:15:05,583: INFO/MainProcess] mingle: searching for neighbors
[2025-10-12 02:15:06,591: INFO/MainProcess] mingle: all alone
[2025-10-12 02:15:06,600: INFO/MainProcess] celery@srv934846 ready.
[2025-10-12 02:15:37,733: ERROR/MainProcess] Received unregistered task of type 'keepa_deals.tasks.update_recent_deals'.
The message has been ignored and discarded.

Did you remember to import the module containing this task?
Or maybe you're using relative imports?

Please see
https://docs.celeryq.dev/en/latest/internals/protocol.html
for more information.

The full contents of the message body was:
b'[[], {}, {"callbacks": null, "errbacks": null, "chain": null, "chord": null}]' (77b)

The full contents of the message headers:
{'lang': 'py', 'task': 'keepa_deals.tasks.update_recent_deals', 'id': '4e48213c-29f3-4910-a812-4397cf94086b', 'shadow': None, 'eta': None, 'expires': None, 'group': None, 'group_index': None, 'retries': 0, 'timelimit': [None, None], 'root_id': '4e48213c-29f3-4910-a812-4397cf94086b', 'parent_id': None, 'argsrepr': '()', 'kwargsrepr': '{}', 'origin': 'gen394612@srv934846', 'ignore_result': False, 'replaced_task_nesting': 0, 'stamped_headers': None, 'stamps': {}}

The delivery info for this task is:
{'exchange': '', 'routing_key': 'celery'}
Traceback (most recent call last):
  File "/var/www/agentarbitrage/venv/lib/python3.10/site-packages/celery/worker/consumer/consumer.py", line 658, in on_task_received
    strategy = strategies[type_]
KeyError: 'keepa_deals.tasks.update_recent_deals'
